{"timestamp":"2025-07-10T12:01:01.558680","level":"info","event":"DAG bundles loaded: dags-folder","logger":"airflow.dag_processing.bundles.manager.DagBundlesManager"}
{"timestamp":"2025-07-10T12:01:01.559339","level":"info","event":"Filling up the DagBag from /opt/airflow/dags/bangalore_home_prices_dag.py","logger":"airflow.models.dagbag.DagBag"}
{"timestamp":"2025-07-10T12:01:01.561957","level":"info","event":"Using MLflow tracking URI: http://mlflow:5000","logger":"root"}
{"timestamp":"2025-07-10T12:01:03.405247","level":"info","event":"Starting model training...","logger":"root"}
{"timestamp":"2025-07-10T12:01:05.253421","level":"warning","event":"Unable to find AWS Connection ID 'aws_default', switching to empty.","logger":"airflow.task.hooks.airflow.providers.amazon.aws.hooks.s3.S3Hook"}
{"timestamp":"2025-07-10T12:01:05.254183","level":"info","event":"No connection ID provided. Fallback on boto3 credential strategy (region_name=None). See: https://boto3.amazonaws.com/v1/documentation/api/latest/guide/configuration.html","logger":"airflow.providers.amazon.aws.hooks.base_aws.BaseSessionFactory"}
{"timestamp":"2025-07-10T12:01:05.657312","level":"info","event":"Found credentials in environment variables.","logger":"botocore.credentials"}
{"timestamp":"2025-07-10T12:01:07.312824","level":"info","event":"Preparing features...","logger":"root"}
{"timestamp":"2025-07-10T12:01:07.364846","level":"info","event":"Splitting data into train and test sets...","logger":"root"}
{"timestamp":"2025-07-10T12:01:07.367786","level":"info","event":"MLflow tracking URI set to: http://localhost:5000","logger":"root"}
{"timestamp":"2025-07-10T12:01:07.399620","level":"warning","event":"Retrying (Retry(total=6, connect=6, read=7, redirect=7, status=7)) after connection broken by 'NewConnectionError('<urllib3.connection.HTTPConnection object at 0x7680b2b1d430>: Failed to establish a new connection: [Errno 111] Connection refused')': /api/2.0/mlflow/experiments/get-by-name?experiment_name=bangalore_home_prices","logger":"urllib3.connectionpool"}
{"timestamp":"2025-07-10T12:01:11.701676","level":"warning","event":"Retrying (Retry(total=5, connect=5, read=7, redirect=7, status=7)) after connection broken by 'NewConnectionError('<urllib3.connection.HTTPConnection object at 0x7680b513b920>: Failed to establish a new connection: [Errno 111] Connection refused')': /api/2.0/mlflow/experiments/get-by-name?experiment_name=bangalore_home_prices","logger":"urllib3.connectionpool"}
{"timestamp":"2025-07-10T12:01:19.740365","level":"warning","event":"Retrying (Retry(total=4, connect=4, read=7, redirect=7, status=7)) after connection broken by 'NewConnectionError('<urllib3.connection.HTTPConnection object at 0x7680b2b65880>: Failed to establish a new connection: [Errno 111] Connection refused')': /api/2.0/mlflow/experiments/get-by-name?experiment_name=bangalore_home_prices","logger":"urllib3.connectionpool"}
{"timestamp":"2025-07-10T12:01:36.469669","level":"warning","event":"Retrying (Retry(total=3, connect=3, read=7, redirect=7, status=7)) after connection broken by 'NewConnectionError('<urllib3.connection.HTTPConnection object at 0x7680b2b64c50>: Failed to establish a new connection: [Errno 111] Connection refused')': /api/2.0/mlflow/experiments/get-by-name?experiment_name=bangalore_home_prices","logger":"urllib3.connectionpool"}
{"timestamp":"2025-07-10T12:02:08.489658","level":"warning","event":"Retrying (Retry(total=2, connect=2, read=7, redirect=7, status=7)) after connection broken by 'NewConnectionError('<urllib3.connection.HTTPConnection object at 0x7680b26082f0>: Failed to establish a new connection: [Errno 111] Connection refused')': /api/2.0/mlflow/experiments/get-by-name?experiment_name=bangalore_home_prices","logger":"urllib3.connectionpool"}
{"timestamp":"2025-07-10T12:03:13.407205","level":"warning","event":"Retrying (Retry(total=1, connect=1, read=7, redirect=7, status=7)) after connection broken by 'NewConnectionError('<urllib3.connection.HTTPConnection object at 0x7680b26084a0>: Failed to establish a new connection: [Errno 111] Connection refused')': /api/2.0/mlflow/experiments/get-by-name?experiment_name=bangalore_home_prices","logger":"urllib3.connectionpool"}
{"timestamp":"2025-07-10T12:05:13.408070","level":"warning","event":"Retrying (Retry(total=0, connect=0, read=7, redirect=7, status=7)) after connection broken by 'NewConnectionError('<urllib3.connection.HTTPConnection object at 0x7680b2608620>: Failed to establish a new connection: [Errno 111] Connection refused')': /api/2.0/mlflow/experiments/get-by-name?experiment_name=bangalore_home_prices","logger":"urllib3.connectionpool"}
{"timestamp":"2025-07-10T12:05:13.409016","level":"error","event":"Task failed with exception","logger":"task","error_detail":[{"exc_type":"MlflowException","exc_value":"API request to http://localhost:5000/api/2.0/mlflow/experiments/get-by-name failed with exception HTTPConnectionPool(host='localhost', port=5000): Max retries exceeded with url: /api/2.0/mlflow/experiments/get-by-name?experiment_name=bangalore_home_prices (Caused by NewConnectionError('<urllib3.connection.HTTPConnection object at 0x7680b26087a0>: Failed to establish a new connection: [Errno 111] Connection refused'))","exc_notes":[],"syntax_error":null,"is_cause":false,"frames":[{"filename":"/home/airflow/.local/lib/python3.12/site-packages/airflow/sdk/execution_time/task_runner.py","lineno":867,"name":"run"},{"filename":"/home/airflow/.local/lib/python3.12/site-packages/airflow/sdk/execution_time/task_runner.py","lineno":1159,"name":"_execute_task"},{"filename":"/home/airflow/.local/lib/python3.12/site-packages/airflow/sdk/bases/operator.py","lineno":397,"name":"wrapper"},{"filename":"/home/airflow/.local/lib/python3.12/site-packages/airflow/providers/standard/operators/python.py","lineno":216,"name":"execute"},{"filename":"/home/airflow/.local/lib/python3.12/site-packages/airflow/providers/standard/operators/python.py","lineno":239,"name":"execute_callable"},{"filename":"/home/airflow/.local/lib/python3.12/site-packages/airflow/sdk/execution_time/callback_runner.py","lineno":81,"name":"run"},{"filename":"/opt/airflow/dags/bangalore_home_prices_dag.py","lineno":25,"name":"train_wrapper"},{"filename":"/opt/airflow/dags/train_model.py","lineno":124,"name":"train_model"},{"filename":"/opt/airflow/dags/mlflow_utils.py","lineno":32,"name":"setup_mlflow"},{"filename":"/home/airflow/.local/lib/python3.12/site-packages/mlflow/tracking/fluent.py","lineno":1901,"name":"get_experiment_by_name"},{"filename":"/home/airflow/.local/lib/python3.12/site-packages/mlflow/tracking/client.py","lineno":1747,"name":"get_experiment_by_name"},{"filename":"/home/airflow/.local/lib/python3.12/site-packages/mlflow/tracking/_tracking_service/client.py","lineno":258,"name":"get_experiment_by_name"},{"filename":"/home/airflow/.local/lib/python3.12/site-packages/mlflow/store/tracking/rest_store.py","lineno":869,"name":"get_experiment_by_name"},{"filename":"/home/airflow/.local/lib/python3.12/site-packages/mlflow/store/tracking/rest_store.py","lineno":135,"name":"_call_endpoint"},{"filename":"/home/airflow/.local/lib/python3.12/site-packages/mlflow/utils/rest_utils.py","lineno":585,"name":"call_endpoint"},{"filename":"/home/airflow/.local/lib/python3.12/site-packages/mlflow/utils/rest_utils.py","lineno":252,"name":"http_request"}],"is_group":false,"exceptions":[]},{"exc_type":"ConnectionError","exc_value":"HTTPConnectionPool(host='localhost', port=5000): Max retries exceeded with url: /api/2.0/mlflow/experiments/get-by-name?experiment_name=bangalore_home_prices (Caused by NewConnectionError('<urllib3.connection.HTTPConnection object at 0x7680b26087a0>: Failed to establish a new connection: [Errno 111] Connection refused'))","exc_notes":[],"syntax_error":null,"is_cause":false,"frames":[{"filename":"/home/airflow/.local/lib/python3.12/site-packages/mlflow/utils/rest_utils.py","lineno":229,"name":"http_request"},{"filename":"/home/airflow/.local/lib/python3.12/site-packages/mlflow/utils/request_utils.py","lineno":237,"name":"_get_http_response_with_retries"},{"filename":"/home/airflow/.local/lib/python3.12/site-packages/requests/sessions.py","lineno":589,"name":"request"},{"filename":"/home/airflow/.local/lib/python3.12/site-packages/requests/sessions.py","lineno":703,"name":"send"},{"filename":"/home/airflow/.local/lib/python3.12/site-packages/requests/adapters.py","lineno":700,"name":"send"}],"is_group":false,"exceptions":[]},{"exc_type":"MaxRetryError","exc_value":"HTTPConnectionPool(host='localhost', port=5000): Max retries exceeded with url: /api/2.0/mlflow/experiments/get-by-name?experiment_name=bangalore_home_prices (Caused by NewConnectionError('<urllib3.connection.HTTPConnection object at 0x7680b26087a0>: Failed to establish a new connection: [Errno 111] Connection refused'))","exc_notes":[],"syntax_error":null,"is_cause":false,"frames":[{"filename":"/home/airflow/.local/lib/python3.12/site-packages/requests/adapters.py","lineno":667,"name":"send"},{"filename":"/home/airflow/.local/lib/python3.12/site-packages/urllib3/connectionpool.py","lineno":871,"name":"urlopen"},{"filename":"/home/airflow/.local/lib/python3.12/site-packages/urllib3/connectionpool.py","lineno":871,"name":"urlopen"},{"filename":"/home/airflow/.local/lib/python3.12/site-packages/urllib3/connectionpool.py","lineno":871,"name":"urlopen"},{"filename":"/home/airflow/.local/lib/python3.12/site-packages/urllib3/connectionpool.py","lineno":871,"name":"urlopen"},{"filename":"/home/airflow/.local/lib/python3.12/site-packages/urllib3/connectionpool.py","lineno":871,"name":"urlopen"},{"filename":"/home/airflow/.local/lib/python3.12/site-packages/urllib3/connectionpool.py","lineno":871,"name":"urlopen"},{"filename":"/home/airflow/.local/lib/python3.12/site-packages/urllib3/connectionpool.py","lineno":871,"name":"urlopen"},{"filename":"/home/airflow/.local/lib/python3.12/site-packages/urllib3/connectionpool.py","lineno":841,"name":"urlopen"},{"filename":"/home/airflow/.local/lib/python3.12/site-packages/urllib3/util/retry.py","lineno":519,"name":"increment"}],"is_group":false,"exceptions":[]},{"exc_type":"NewConnectionError","exc_value":"<urllib3.connection.HTTPConnection object at 0x7680b26087a0>: Failed to establish a new connection: [Errno 111] Connection refused","exc_notes":[],"syntax_error":null,"is_cause":true,"frames":[{"filename":"/home/airflow/.local/lib/python3.12/site-packages/urllib3/connectionpool.py","lineno":787,"name":"urlopen"},{"filename":"/home/airflow/.local/lib/python3.12/site-packages/urllib3/connectionpool.py","lineno":493,"name":"_make_request"},{"filename":"/home/airflow/.local/lib/python3.12/site-packages/urllib3/connection.py","lineno":445,"name":"request"},{"filename":"/usr/local/lib/python3.12/http/client.py","lineno":1333,"name":"endheaders"},{"filename":"/usr/local/lib/python3.12/http/client.py","lineno":1093,"name":"_send_output"},{"filename":"/usr/local/lib/python3.12/http/client.py","lineno":1037,"name":"send"},{"filename":"/home/airflow/.local/lib/python3.12/site-packages/urllib3/connection.py","lineno":276,"name":"connect"},{"filename":"/home/airflow/.local/lib/python3.12/site-packages/urllib3/connection.py","lineno":213,"name":"_new_conn"}],"is_group":false,"exceptions":[]},{"exc_type":"ConnectionRefusedError","exc_value":"[Errno 111] Connection refused","exc_notes":[],"syntax_error":null,"is_cause":true,"frames":[{"filename":"/home/airflow/.local/lib/python3.12/site-packages/urllib3/connection.py","lineno":198,"name":"_new_conn"},{"filename":"/home/airflow/.local/lib/python3.12/site-packages/urllib3/util/connection.py","lineno":85,"name":"create_connection"},{"filename":"/home/airflow/.local/lib/python3.12/site-packages/urllib3/util/connection.py","lineno":73,"name":"create_connection"}],"is_group":false,"exceptions":[]}]}
